<!--

MODEL: Univewrsal Robots UR5 + Robotiq S Model 3 Finger Gripper
AUTHOR: Andrea Franceschetti @IASLAB Research Group
UNIVERSITY: University of Padua
DEPARTMENT: Departement of Information Engineering DEI
Control Engineering / Automation Engineering

-->


<!--Link  MuJoCo modeling: http://www.mujoco.org/book/modeling.html-->

<mujoco model="ur5gripper">
    <compiler angle="radian"
              inertiafromgeom="true"
              texturedir="textures/"
              meshdir="mesh/visual/"/>
    <option timestep="2e-3"
            iterations="100"
            tolerance="1e-10"
            impratio="10"/>
    <!-- <size njmax="600" nconmax="150" nstack="300000"/> -->

    <default>
        <site rgba="0.8 0.6 0.7 0.3" type="ellipsoid" group="3"/>
        <geom contype='1' conaffinity='1' condim='4' margin="1e-3" solref=".01 1" solimp=".99 .99 .01"/>
        <joint armature="0.01" damping=".1"/>
        <default class="UR5">
            <joint damping='65'/>
        </default>
        <default class="UR5e">
            <joint damping='45'/>
        </default>
        <default class="GRIPPER">
            <joint damping='5'/>
        </default>
    </default>

    <visual>
        <map fogstart="3" fogend="5" znear="0.05"/>
        <quality shadowsize="2048"/>
        <scale framelength="0.1"
               framewidth="0.005"
               contactwidth="0.1"
               contactheight="0.005"
               forcewidth="0.01"
        />
    </visual>

    <!--Assets-->
    <asset>
        <!--Meshes-->
        <mesh name="base" file="mesh/base.stl"/>
        <mesh name="shoulder" file="mesh/shoulder.stl"/>
        <mesh name="upperarm" file="mesh/upperarm.stl"/>
        <mesh name="forearm" file="mesh/forearm.stl"/>
        <mesh name="wrist1" file="mesh/wrist1.stl"/>
        <mesh name="wrist2" file="mesh/wrist2.stl"/>
        <mesh name="wrist3" file="mesh/wrist3.stl"/>
        <mesh name="gripperpalm" file="mesh/palm.STL"/>
        <mesh name="link_0" file="mesh/link_0.STL"/>
        <mesh name="link_1" file="mesh/link_1.STL"/>
        <mesh name="link_2" file="mesh/link_2.STL"/>
        <mesh name="link_3" file="mesh/link_3.STL"/>

        <mesh name="robotiq_85_base_link_coarse" file="mesh/robotiq_85_base_link_coarse.STL"/>
        <mesh name="inner_knuckle_coarse" file="mesh/inner_knuckle_coarse.STL"/>
        <mesh name="inner_finger_coarse" file="mesh/inner_finger_coarse.STL"/>
        <mesh name="outer_knuckle_coarse" file="mesh/outer_knuckle_coarse.STL"/>
        <mesh name="outer_finger_coarse" file="mesh/outer_finger_coarse.STL"/>

        <!--Textures-->
        <texture name="ur5_tex" type="2d" builtin="flat" height="32" width="32" rgb1="0.45 0.45 0.45"/>
        <texture name="gripper_tex" type="2d" builtin="flat" height="32" width="32" rgb1="0.45 0.45 0.45" rgb2="0 0 0"/>
        <texture name="bench_tex" type="2d" builtin="flat" height="32" width="32" rgb1="0.7 0.7 0.7"/>
        <texture name="sky_tex" type="skybox" builtin="gradient" width="100" height="100" rgb1="1 1 1"
                 rgb2="0.3 0.3 0.8"/>
        <texture name="texgeom" type="cube" builtin="flat" mark="cross" width="127" height="1278" rgb1="0.8 0.6 0.4"
                 rgb2="0.8 0.6 0.4" markrgb="1 1 1" random="0.01"/>
        <texture name="floor_tex" type="2d" builtin="checker" rgb1=".2 .3 .4" rgb2=".1 .2 .3" width="100" height="100"/>
        <texture name="wood" type="cube" file="texture/wood2.png"/>
        <texture name="metal" type="cube" file="texture/metal2.png"/>
        <!--Materials-->
        <material name="ur5_mat" texture="ur5_tex" shininess="0.9" specular="0.75" reflectance="0.3"/>
        <material name="gripper_mat" texture="gripper_tex" shininess="0.9" specular="0.75" reflectance="0.4"/>
        <material name='floor_mat' texture="floor_tex" shininess="0.8" texrepeat="10 10" specular="0.7"
                  reflectance="0.5"/>
        <material name='geom' texture="texgeom" texuniform="true"/>
        <material name="bench_mat" texture="metal" shininess="0.1" specular="0.5" reflectance="0.2"/>
        <material name="tablecube" texture="wood" rgba=".8 .8 .8 1"/>
    </asset>

    <!--Contacts-->
    <contact>
        <!--        <exclude body1="box_link" body2="base_link"/>-->
        <!--        <exclude body1="base_link" body2="shoulder_link"/>-->
        <!--        <exclude body1="shoulder_link" body2="upper_arm_link"/>-->
        <!--        <exclude body1="upper_arm_link" body2="forearm_link"/>-->
        <!--        <exclude body1="forearm_link" body2="wrist_1_link"/>-->
        <!--        <exclude body1="wrist_1_link" body2="wrist_2_link"/>-->
        <!--        <exclude body1="wrist_2_link" body2="wrist_3_link"/>-->
        <!--        <exclude body1="ee_link" body2="wrist_3_link"/>-->
    </contact>


    <!--MODEL DESCRIPTION-->
    <worldbody>
        <!--Lighting parameters-->
        <light name="light3" mode="targetbody" target="box_link" directional="true" pos="1 -1 3"/>
        <!-- <light name="light3" mode="targetbody" target="box_link" directional="true" pos="1 1 3" /> -->
        <!--Camera parameters-->
        <camera name="main1" mode="fixed" target="ee_link" pos="2 2 2.7" axisangle="2 2 -2 1"/>
        <camera name="top_down" mode="fixed" target="ee_link" pos="0 -0.6 2.0" axisangle="2 2 2 0"/>
        <camera name="side" mode="fixed" target="ee_link" pos="0.8 -0.6 1.0" quat="0.5 0.5 0.5 0.5"/>

        <!--Robot UR5-->
        <body name="box_link" pos="0 0 -1">
            <!--<geom size=".3 .2 .435" type="box" material="bench_mat"/>-->
            <geom size=".29 .19 .03" pos="0 0 0.4" type="box" material="bench_mat"/>
            <geom size=".29 .19 .03" pos="0 0 -0.2" type="box" material="bench_mat"/>
            <geom size=".04 .04 .435" pos=".26 .16 0" type="box" material="bench_mat"/>
            <geom size=".04 .04 .435" pos="-.26 .16 0" type="box" material="bench_mat"/>
            <geom size=".04 .04 .435" pos=".26 -.16 0" type="box" material="bench_mat"/>
            <geom size=".04 .04 .435" pos="-.26 -.16 0" type="box" material="bench_mat"/>
            <inertial pos="0 0 0" mass="1000" diaginertia="0 0 0"/>
            <body name="base" pos="0 0 0.435">
                <inertial pos="0 0 0" quat="0.5 0.5 -0.5 0.5" mass="4" diaginertia="0.0072 0.00443333 0.00443333"/>
                <geom type="mesh" mesh="base" material="ur5_mat"/>
                <body name="shoulder_link" pos="0 0 0.089159">
                    <inertial pos="0 0 0" mass="3.7" diaginertia="0.0102675 0.0102675 0.00666"/>
                    <joint name="shoulder_pan_joint" class="UR5" pos="0 0 0" axis="0 0 1" limited="false"/>
                    <geom type="mesh" mesh="shoulder" material="ur5_mat"/>
                    <body name="upper_arm_link" pos="0 0.13585 0" quat="0.707107 0 0.707107 0">
                        <inertial pos="0 0 0.28" mass="8.393" diaginertia="0.226891 0.226891 0.0151074"/>
                        <joint name="shoulder_lift_joint" class="UR5" pos="0 0 0" axis="0 1 0" limited="true"
                               range="-3.1416 0"/> <!--Range= -3.14159 3.14159-->
                        <geom type="mesh" mesh="upperarm" material="ur5_mat"/>
                        <body name="forearm_link" pos="0 -0.1197 0.425">
                            <inertial pos="0 0 0.25" mass="2.275" diaginertia="0.0494433 0.0494433 0.004095"/>
                            <joint name="elbow_joint" class="UR5" pos="0 0 0" axis="0 1 0" limited="true"
                                   range="0 2.8274"/>
                            <geom type="mesh" mesh="forearm" material="ur5_mat"/>
                            <body name="wrist_1_link" pos="0 0 0.39225" quat="0.707107 0 0.707107 0">
                                <inertial pos="0 0 0" quat="0.5 0.5 -0.5 0.5" mass="1.219"
                                          diaginertia="0.21942 0.111173 0.111173"/>
                                <joint name="wrist_1_joint" class="UR5e" pos="0 0 0" axis="0 1 0" limited="true"
                                       range="-3.1416 0"/>
                                <geom type="mesh" mesh="wrist1" material="ur5_mat"/>
                                <body name="wrist_2_link" pos="0 0.093 0">
                                    <inertial pos="0 0 0" quat="0.5 0.5 -0.5 0.5" mass="1.219"
                                              diaginertia="0.21942 0.111173 0.111173"/>
                                    <joint name="wrist_2_joint" class="UR5e" pos="0 0 0" axis="0 0 1" limited="false"/>
                                    <geom type="mesh" mesh="wrist2" material="ur5_mat"/>
                                    <body name="wrist_3_link" pos="0 0 0.09465">
                                        <inertial pos="0 0 0" quat="0.5 0.5 -0.5 0.5" mass="0.1879"
                                                  diaginertia="0.033822 0.0171365 0.0171365"/>
                                        <joint name="wrist_3_joint" class="UR5e" pos="0 0 0" axis="0 1 0"
                                               limited="false"/>
                                        <geom type="mesh" mesh="wrist3" material="ur5_mat"/>
                                        <body name="hand" pos="0 0.0823 0" quat="0.707 -0.707 0 0">

                                            <camera mode="fixed" name="eye_in_hand" pos="0.05 0 0"
                                                    quat="0 0.707108 0.707108 0" fovy="75"/>

                                        </body>
                                    </body>
                                </body>
                            </body>
                        </body>
                    </body>
                </body>
            </body>
            <!--            <body name="base" pos="0 0 0" quat="1.7949e-09 0 0 -1">-->
            <!--                <inertial pos="0 0 0" quat="1.7949e-09 0 0 -1" mass="0" diaginertia="0 0 0"/>-->
            <!--            </body>-->
        </body>


    </worldbody>


    <!--ACTUATORS-->
    <actuator>
        <!--UR5-->
        <position name='shoulder_pan' ctrllimited="true" ctrlrange="-3141.6 3141.6" forcelimited="true"
                  forcerange="-100000 100000" joint='shoulder_pan_joint' kv='30'
                  kp="80"/>
        <position name='shoulder_lift' ctrllimited="true" ctrlrange="-3.1416 0" forcelimited="true"
                  forcerange="-100000 100000" joint='shoulder_lift_joint'
                  kv="150" kp="3500"/>
        <position name='forearm' ctrllimited="true" ctrlrange="0 2.8274" forcelimited="true" forcerange="-100000 100000"
                  joint='elbow_joint' kv='100'
                  kp="3000"/>
        <position name='wrist_1' ctrllimited="true" ctrlrange="-3.1416 0" forcelimited="true"
                  forcerange="-100000 100000" joint='wrist_1_joint' kv='20'
                  kp="400"/>
        <position name='wrist_2' ctrllimited="true" ctrlrange="-3141.6 3141.6" forcelimited="true"
                  forcerange="-100000 100000" joint='wrist_2_joint' kv='20'
                  kp="100"/>
        <position name='wrist_3' ctrllimited="true" ctrlrange="-3141.6 3141.6" forcelimited="true"
                  forcerange="-100000 100000" joint='wrist_3_joint' kp="10" kv="2"/>

    </actuator>

    <sensor>
        <jointpos joint="shoulder_pan_joint" name="pos_right_j1"/>
        <jointpos joint="shoulder_lift_joint" name="pos_right_j2"/>
        <jointpos joint="elbow_joint" name="pos_right_j3"/>
        <jointpos joint="wrist_1_joint" name="pos_right_j4"/>
        <jointpos joint="wrist_2_joint" name="pos_right_j5"/>
        <jointpos joint="wrist_3_joint" name="pos_right_j6"/>
    </sensor>
</mujoco>
